<?xml version="1.0" ?>
<!-- =================================================================================== -->
<!-- |    This document was autogenerated by xacro from ./urdf.xacro                   | -->
<!-- |    EDITING THIS FILE BY HAND IS NOT RECOMMENDED                                 | -->
<!-- =================================================================================== -->
<robot name="panda_no_base" xmlns:xacro="http://www.ros.org/wiki/xacro">
  <material name="panda_white">
    <color rgba="1. 1. 1. 1."/>
  </material>
  <material name="panda_red">
    <color rgba="1. 1. 1. 1."/>
  </material>

  <link name="panda_arm_base_link">
    <inertial>
      <origin rpy="0 0 0.0" xyz="0 0 0"/>
      <mass value="0.00"/>
      <inertia ixx="0.00" ixy="0" ixz="0" iyy="0.00" iyz="0" izz="0.00"/>
    </inertial>    
  </link>

  <link name="panda_l0">
    <inertial>
      <origin rpy="0 0 0.0" xyz="0 0 0"/>
      <mass value="0.00"/>
      <inertia ixx="0.00" ixy="0" ixz="0" iyy="0.00" iyz="0" izz="0.00"/>
    </inertial>
  </link>
  <joint name="panda_j0" type="prismatic">
    <limit effort="10000" lower="-5" upper="5" velocity="1.328"/>
    <origin rpy="0 0 0" xyz="0 0 0"/>    
    <axis xyz="1 0 0"/>
    <parent link="panda_arm_base_link"/>
    <child link="panda_l0"/>
  </joint>

  <link name="panda_l1">
    <inertial>
      <origin rpy="0 0 0.0" xyz="0 0 0"/>
      <mass value="0.00"/>
      <inertia ixx="0.00" ixy="0" ixz="0" iyy="0.00" iyz="0" izz="0.00"/>
    </inertial>    
  </link>
  <joint name="panda_j1" type="prismatic">
    <limit effort="10000" lower="-5" upper="5" velocity="1.328"/>
    <axis xyz="0 1 0"/>
    <parent link="panda_l0"/>
    <child link="panda_l1"/>
  </joint>

  <link name="panda_l2">
    <inertial>
      <origin rpy="0 0 0.0" xyz="0 0 0"/>
      <mass value="0.00"/>
      <inertia ixx="0.00" ixy="0" ixz="0" iyy="0.00" iyz="0" izz="0.00"/>
    </inertial>
  </link>  
  <joint name="panda_j2" type="prismatic">
    <limit effort="10000" lower="-5" upper="5" velocity="1.328"/>
    <axis xyz="0 0 1"/>
    <parent link="panda_l1"/>
    <child link="panda_l2"/>
  </joint>
  
  <!--Let's do a ball joint-->
  <link name="panda_l3r">
    <!-- <visual> -->
    <!--   <origin rpy="0 0 0" xyz="0 0 0"/> -->
    <!--   <geometry> -->
    <!--     <sphere radius="0.05"/> -->
    <!--   </geometry> -->
    <!--   <material name="darkgray"/> -->
    <!-- </visual> -->
  </link>
  <joint name="panda_j3r" type="continuous">
    <origin rpy="0 0 0" xyz="0 0 0"/>
    <parent link="panda_l2"/>
    <child link="panda_l3r"/>
    <axis xyz="1 0 0"/>
    <!-- <limit effort="400." /> -->
    <!-- <dynamics friction="1.0"/> -->
    <!-- <limit effort="40.0" lower="-4.0" upper="4.0"
         velocity="1.957"/> -->
  </joint>

  <link name="panda_l3p">
    <!-- <visual> -->
    <!--   <origin rpy="0 0 0" xyz="0 0 0"/> -->
    <!--   <geometry> -->
    <!--     <sphere radius="0.05"/> -->
    <!--   </geometry> -->
    <!--   <material name="darkgray"/> -->
    <!-- </visual> -->
  </link>
  <joint name="panda_j3p" type="continuous">
    <origin rpy="0 0 0" xyz="0 0 0"/>
    <parent link="panda_l3r"/>
    <child link="panda_l3p"/>
    <axis xyz="0 1 0"/>
    <!-- <limit effort="400." /> -->
    <!-- <dynamics damping="0.7" friction="0.0"/>     -->
    <!-- <limit effort="40.0" lower="-4.0" upper="4.0" velocity="1.957"/> -->
  </joint>

  <link name="panda_l3y">
    <!-- <visual> -->
    <!--   <origin rpy="0 0 0" xyz="0 0 0"/> -->
    <!--   <geometry> -->
    <!--     <sphere radius="0.05"/> -->
    <!--   </geometry> -->
    <!--   <material name="darkgray"/> -->
    <!-- </visual> -->
  </link>
  <joint name="panda_j3y" type="continuous">
    <origin rpy="0 0 0" xyz="0 0 0"/>
    <parent link="panda_l3p"/>
    <child link="panda_l3y"/>
    <axis xyz="0 0 1"/>
    <!-- <limit effort="400." /> -->
    <!-- <dynamics damping="0.7" friction="0.0"/>     -->
    <!-- <limit effort="40.0" lower="-4.0" upper="4.0" velocity="1.957"/> -->
  </joint>
  <link name="panda_link8">
  	 <inertial>
      <origin rpy="0 0 0" xyz="0 0 0"/>
       <mass value="0.0"/>
       <inertia ixx="0.1" ixy="0" ixz="0" iyy="0.1" iyz="0" izz="0.1"/>
    </inertial>
  </link>
  <joint name="panda_joint8" type="fixed">
    <origin rpy="0 0 0" xyz="0 0 0.107"/>
    <parent link="panda_l3y"/>
    <child link="panda_link8"/>
    <axis xyz="0 0 0"/>
  </joint>
  <joint name="panda_hand_joint" type="fixed">
    <parent link="panda_link8"/>
    <child link="panda_hand"/>
    <origin rpy="0 0 -0.785398163397" xyz="0 0 0"/>
  </joint>
  <link name="panda_hand">
  	<inertial>
      <origin rpy="0 0 0" xyz="0 0 0.04"/>
       <mass value=".81"/>
       <inertia ixx="0.1" ixy="0" ixz="0" iyy="0.1" iyz="0" izz="0.1"/>
    </inertial>
    <visual>
      <geometry>
        <mesh filename="package://meshes/visual/hand.obj"/>
      </geometry>
      <material name="panda_white"/>
    </visual>
    <collision>
      <geometry>
        <mesh filename="package://meshes/collision/hand.obj"/>
      </geometry>
      <material name="panda_white"/>
    </collision>
  </link>
  <link name="panda_leftfinger">
       <contact>
      <friction_anchor/>
      <stiffness value="30000.0"/>
      <damping value="1000.0"/>
      <spinning_friction value="0.1"/>
      <lateral_friction value="1.0"/>
    </contact>
  	<inertial>
      <origin rpy="0 0 0" xyz="0 0.01 0.02"/>
       <mass value="0.1"/>
       <inertia ixx="0.1" ixy="0" ixz="0" iyy="0.1" iyz="0" izz="0.1"/>
    </inertial>
    <visual>
      <geometry>
        <mesh filename="package://meshes/visual/finger.obj"/>
      </geometry>
      <material name="panda_white"/>
    </visual>
    <collision>
      <geometry>
        <mesh filename="package://meshes/collision/finger.obj"/>
      </geometry>
      <material name="panda_white"/>
    </collision>
  </link>
  <link name="panda_rightfinger">
        <contact>
      <friction_anchor/>
      <stiffness value="30000.0"/>
      <damping value="1000.0"/>
      <spinning_friction value="0.1"/>
      <lateral_friction value="1.0"/>
    </contact>

  	<inertial>
      <origin rpy="0 0 0" xyz="0 -0.01 0.02"/>
       <mass value="0.1"/>
       <inertia ixx="0.1" ixy="0" ixz="0" iyy="0.1" iyz="0" izz="0.1"/>
    </inertial>
    <visual>
      <origin rpy="0 0 3.14159265359" xyz="0 0 0"/>
      <geometry>
        <mesh filename="package://meshes/visual/finger.obj"/>
      </geometry>
      <material name="panda_white"/>
    </visual>
    <collision>
      <origin rpy="0 0 3.14159265359" xyz="0 0 0"/>
      <geometry>
        <mesh filename="package://meshes/collision/finger.obj"/>
      </geometry>
      <material name="panda_white"/>
    </collision>
  </link>
  <joint name="panda_finger_joint1" type="prismatic">
    <parent link="panda_hand"/>
    <child link="panda_leftfinger"/>
    <origin rpy="0 0 0" xyz="0 0 0.0584"/>
    <axis xyz="0 1 0"/>
    <limit effort="20" lower="0.0" upper="0.04" velocity="0.2"/>
  </joint>
  <joint name="panda_finger_joint2" type="prismatic">
    <parent link="panda_hand"/>
    <child link="panda_rightfinger"/>
    <origin rpy="0 0 0" xyz="0 0 0.0584"/>
    <axis xyz="0 -1 0"/>
    <limit effort="20" lower="0.0" upper="0.04" velocity="0.2"/>
    <mimic joint="panda_finger_joint1"/>
  </joint>
   <link name="panda_grasptarget">
 <!-- <inertial> -->
 <!--      <origin rpy="0 0 0" xyz="0 0 0"/> -->
 <!--       <mass value="0.0"/> -->
 <!--       <inertia ixx="0.1" ixy="0" ixz="0" iyy="0.1" iyz="0" izz="0.1"/> -->
 <!--    </inertial> -->
   </link>
   <joint name="panda_grasptarget_hand" type="fixed">
    <parent link="panda_hand"/>
    <child link="panda_grasptarget"/>
    <origin rpy="0 0 0" xyz="0 0 0.105"/>
  </joint>

</robot>
